Workbook

Sheet Legend
A1: How to use this workbook
A3: Purpose | B3: Log real (paper or live) trades taken with the manipulation-leg / liquidity-sweep strategy (stdvbot/manipulation_leg_strategy.py) and see profitability + MyFundedFutures Pro 50K compliance metrics update automatically.
A4: Where to enter data | B4: 'Trade Log' sheet, starting at row 3 (row 2 is a labeled SAMPLE row — delete its contents, or the whole row, once you have real trades; do not delete the formulas in columns I, L, O, X, Y, Z, AA, AB, AC, AD, AE, AF, they auto-compute).
A5: Yellow cells | B5: The only cells meant to be typed into: Dashboard!B4:B11 (account/instrument assumptions), 'Trade Log' input columns (A/D/J/K/M/N/P/Q/R/S/T/U/V/W/AG are formulas or free entry — see column-by-column notes below), and 'Daily Summary'!A (one date per row you traded).
A6: Killzone | B6: Asia (20:00 local) or NY (09:30 local). London is not traded per the strategy spec.
A7: Daily Bias / Regime | B7: Read from the higher-timeframe leg (Daily/4H) and Kaufman's Efficiency Ratio — see docs/manipulation_leg_strategy.md §1 and §4. Record what the bot/your analysis determined at the time of the trade.
A8: Leg Direction vs Trade Direction | B8: Trade direction should equal leg direction (corrected rule — an up leg gives a long entry). Column O flags 'CHECK' if they don't match, as a sanity check against the earlier (wrong) 'opposite the leg' version.
A9: Level Grade | B9: Auto-computed from the fib multiple touched (column K): >= the A+ threshold (Dashboard!B11, default 4.5) = 'A+' (near-standalone signal), else 'B-' (needs confluence).
A10: Confluence Score | B10: 0-4: count of candlestick pattern / VWAP proximity / round-number proximity / POI alignment checks that passed on the touching candle. See spec §3.
A11: Risk ($) / PnL ($) | B11: Computed from entry/stop/exit prices, contracts, and the tick size/value assumptions on the Dashboard (defaults are MNQ: 0.25 tick size, $0.50/tick).
A12: R Multiple | B12: PnL ($) / Risk ($) — how many multiples of planned risk the trade returned.
A13: Cumulative / Peak Equity, Drawdown | B13: Chained down the Trade Log (column AD/AE/AF) starting from Dashboard!B4 (Starting Balance); the sample row (row 2) is excluded from this chain so it doesn't distort real results.
A14: Daily Summary sheet | B14: Add one row per day you traded (column A, a date already present in the Trade Log). Everything else recomputes automatically, including a running EOD trailing high-water-mark / MLL floor check (MFF Pro 50K: $2,000 MLL, lock point $52,100).
... A17: Not covered yet | B17: This workbook analyzes trades you log manually. It does not ingest raw OHLC candles — backtesting against real 1-minute data happens in stdvbot (see examples/run_manipulation_leg_backtest.py). Feed this sheet real (paper or live) trade results once you're executing, not raw candles.

Sheet Dashboard
A1: STDVBOT — Manipulation-Leg Strategy — Trial Data Dashboard
A3: Account & Instrument Assumptions (edit yellow cells)
A4: Starting Balance ($) | B4: 50000
A5: Max Loss Limit / MLL ($) | B5: 2000
A6: Profit Target ($) | B6: 3000
A7: Drawdown Lock Point ($, EOD trailing cap) | B7: 52100
A8: Consistency Rule — max single day as % of total profit | B8: 0.5
A9: Instrument Tick Size (MNQ) | B9: 0.25
A10: Instrument Tick Value ($ per tick, MNQ) | B10: 0.5
A11: A+ Grade Threshold (fib level multiple) | B11: 4.5
A13: Performance Summary (auto-computed from Trade Log)
A14: Total Trades Logged | B14: =COUNT('Trade Log'!$AA$3:$AA$152)
A15: Wins | B15: =COUNTIF('Trade Log'!$AC$3:$AC$152,1)
A16: Losses | B16: =COUNTIF('Trade Log'!$AC$3:$AC$152,0)
A17: Win Rate % | B17: =IFERROR(B15/B14,"")
A18: Gross Profit ($) | B18: =SUMIF('Trade Log'!$AA$3:$AA$152,">0")
A19: Gross Loss ($) | B19: =SUMIF('Trade Log'!$AA$3:$AA$152,"<0")
A20: Profit Factor (Gross Profit / |Gross Loss|) | B20: =IFERROR(B18/ABS(B19),"")
A21: Net P&L ($) | B21: =SUM('Trade Log'!$AA$3:$AA$152)
A22: Net P&L (% of Starting Balance) | B22: =IFERROR(B21/B4,"")
A23: Average Win ($) | B23: =IFERROR(AVERAGEIF('Trade Log'!$AA$3:$AA$152,">0"),"")
A24: Average Loss ($) | B24: =IFERROR(AVERAGEIF('Trade Log'!$AA$3:$AA$152,"<0"),"")
A25: Average R Multiple | B25: =IFERROR(AVERAGE('Trade Log'!$AB$3:$AB$152),"")
A26: Expectancy per Trade ($) | B26: =IFERROR(B21/B14,"")
A27: Current Equity ($) | B27: =B4+B21
A28: Max Drawdown ($, peak-to-trough) | B28: =MAX('Trade Log'!$AF$3:$AF$152)
A29: Max Drawdown (%) | B29: =IFERROR(B28/MAX('Trade Log'!$AE$3:$AE$152),"")
A31: Prop-Firm Compliance — MyFundedFutures Pro 50K
A32: Distance to Profit Target ($) | B32: =B6-B21
A33: High-Water Mark, capped at Lock Point ($) | B33: =MIN($B$7,MAX($B$4,MAX('Trade Log'!$AD$3:$AD$152)))
A34: MLL Floor ($) = HWM - MLL | B34: =B33-B5
A35: Cushion to Floor ($) | B35: =B27-B34
A36: Breach Status | B36: =IF(B27<B34,"BREACH","OK")
A37: Consistency Check (best day / net profit) | B37: =IFERROR(MAX('Daily Summary'!$E$2:$E$151)/MAX(B21,0.01),"")
A38: Consistency Rule Status | B38: =IF(B37="","No data yet",IF(B37<=B8,"OK","VIOLATION"))
A39: Days Traded (from Daily Summary) | B39: =COUNTA('Daily Summary'!$A$2:$A$151)
A41: Breakdown by Killzone
A42: Killzone | B42: Trades | C42: Win Rate | D42: Net P&L ($) | E42: Avg R
A43: Asia | B43: =COUNTIF('Trade Log'!$C$3:$C$152,"Asia") | C43: =IFERROR(COUNTIFS('Trade Log'!$C$3:$C$152,"Asia",'Trade Log'!$AC$3:$AC$152,1)/B43,"") | D43: =SUMIFS('Trade Log'!$AA$3:$AA$152,'Trade Log'!$C$3:$C$152,"Asia") | E43: =IFERROR(AVERAGEIFS('Trade Log'!$AB$3:$AB$152,'Trade Log'!$C$3:$C$152,"Asia"),"")
A44: NY | B44: =COUNTIF('Trade Log'!$C$3:$C$152,"NY") | C44: =IFERROR(COUNTIFS('Trade Log'!$C$3:$C$152,"NY",'Trade Log'!$AC$3:$AC$152,1)/B44,"") | D44: =SUMIFS('Trade Log'!$AA$3:$AA$152,'Trade Log'!$C$3:$C$152,"NY") | E44: =IFERROR(AVERAGEIFS('Trade Log'!$AB$3:$AB$152,'Trade Log'!$C$3:$C$152,"NY"),"")
...

Sheet Trade Log
A1: Trade # | B1: Date | C1: Killzone | D1: Daily Bias | E1: Regime | F1: Leg Direction | G1: Leg Origin Price | H1: Leg Extreme Price | I1: Leg Range (pts) | J1: Leg Candle Count | K1: Level Multiple Touched | L1: Level Grade | M1: Confluence Score (0-4) | N1: Trade Direction | O1: Direction Check | P1: Entry Time | Q1: Entry Price | R1: Stop Price | S1: Target Price | T1: Exit Time | U1: Exit Price | V1: Exit Reason | W1: Contracts | X1: Risk ($) | Y1: Points P/L | Z1: Ticks P/L | AA1: PnL ($) | AB1: R Multiple | AC1: Win (1/0) | AD1: Cumulative Equity ($) | AE1: Running Peak Equity ($) | AF1: Drawdown ($) | AG1: Notes
A2: EX | B2: 2026-01-15 | C2: NY | D2: Down | E2: Ranging | F2: Up | G2: 15000 | H2: 15012 | I2: =IFERROR(ABS(H2-G2),"") | J2: 3 | K2: 2.5 | L2: =IF(K2="","",IF(K2>=Dashboard!$B$11,"A+","B-")) | M2: 2 | N2: Long | O2: =IF(OR(N2="",F2=""),"",IF(OR(AND(F2="Up",N2="Long"),AND(F2="Down",N2="Short")),"OK","CHECK")) | P2: 09:34 | Q2: 14970 | R2: 14952 | S2: 14990 | T2: 10:15 | U2: 14990 | V2: Target | W2: 2 | X2: =IFERROR(ABS(Q2-R2)/Dashboard!$B$9*Dashboard!$B$10*W2,"") | Y2: =IFERROR(IF(N2="Long",U2-Q2,IF(N2="Short",Q2-U2,"")),"") | Z2: =IFERROR(Y2/Dashboard!$B$9,"") | AA2: =IFERROR(Z2*Dashboard!$B$10*W2,"") | AB2: =IFERROR(AA2/X2,"") | AC2: =IF(AA2="","",IF(AA2>0,1,0)) | AD2: =Dashboard!$B$4+IF(AA2="",0,AA2) | AE2: =AD2 | AF2: =AE2-AD2 | AG2: SAMPLE ROW - delete before entering real data. Shows expected format only.
A3: =ROW()-2 | I3: =IFERROR(ABS(H3-G3),"") | L3: =IF(K3="","",IF(K3>=Dashboard!$B$11,"A+","B-")) | O3: =IF(OR(N3="",F3=""),"",IF(OR(AND(F3="Up",N3="Long"),AND(F3="Down",N3="Short")),"OK","CHECK")) | X3: =IFERROR(ABS(Q3-R3)/Dashboard!$B$9*Dashboard!$B$10*W3,"") | Y3: =IFERROR(IF(N3="Long",U3-Q3,IF(N3="Short",Q3-U3,"")),"") | Z3: =IFERROR(Y3/Dashboard!$B$9,"") | AA3: =IFERROR(Z3*Dashboard!$B$10*W3,"") | AB3: =IFERROR(AA3/X3,"") | AC3: =IF(AA3="","",IF(AA3>0,1,0)) | AD3: =Dashboard!$B$4+IF(AA3="",0,AA3) | AE3: =AD3 | AF3: =AE3-AD3
A4: =ROW()-2 | I4: =IFERROR(ABS(H4-G4),"") | L4: =IF(K4="","",IF(K4>=Dashboard!$B$11,"A+","B-")) | O4: =IF(OR(N4="",F4=""),"",IF(OR(AND(F4="Up",N4="Long"),AND(F4="Down",N4="Short")),"OK","CHECK")) | X4: =IFERROR(ABS(Q4-R4)/Dashboard!$B$9*Dashboard!$B$10*W4,"") | Y4: =IFERROR(IF(N4="Long",U4-Q4,IF(N4="Short",Q4-U4,"")),"") | Z4: =IFERROR(Y4/Dashboard!$B$9,"") | AA4: =IFERROR(Z4*Dashboard!$B$10*W4,"") | AB4: =IFERROR(AA4/X4,"") | AC4: =IF(AA4="","",IF(AA4>0,1,0)) | AD4: =AD3+IF(AA4="",0,AA4) | AE4: =MAX(AE3,AD4) | AF4: =AE4-AD4
A5: =ROW()-2 | I5: =IFERROR(ABS(H5-G5),"") | L5: =IF(K5="","",IF(K5>=Dashboard!$B$11,"A+","B-")) | O5: =IF(OR(N5="",F5=""),"",IF(OR(AND(F5="Up",N5="Long"),AND(F5="Down",N5="Short")),"OK","CHECK")) | X5: =IFERROR(ABS(Q5-R5)/Dashboard!$B$9*Dashboard!$B$10*W5,"") | Y5: =IFERROR(IF(N5="Long",U5-Q5,IF(N5="Short",Q5-U5,"")),"") | Z5: =IFERROR(Y5/Dashboard!$B$9,"") | AA5: =IFERROR(Z5*Dashboard!$B$10*W5,"") | AB5: =IFERROR(AA5/X5,"") | AC5: =IF(AA5="","",IF(AA5>0,1,0)) | AD5: =AD4+IF(AA5="",0,AA5) | AE5: =MAX(AE4,AD5) | AF5: =AE5-AD5
A6: =ROW()-2 | I6: =IFERROR(ABS(H6-G6),"") | L6: =IF(K6="","",IF(K6>=Dashboard!$B$11,"A+","B-")) | O6: =IF(OR(N6="",F6=""),"",IF(OR(AND(F6="Up",N6="Long"),AND(F6="Down",N6="Short")),"OK","CHECK")) | X6: =IFERROR(ABS(Q6-R6)/Dashboard!$B$9*Dashboard!$B$10*W6,"") | Y6: =IFERROR(IF(N6="Long",U6-Q6,IF(N6="Short",Q6-U6,"")),"") | Z6: =IFERROR(Y6/Dashboard!$B$9,"") | AA6: =IFERROR(Z6*Dashboard!$B$10*W6,"") | AB6: =IFERROR(AA6/X6,"") | AC6: =IF(AA6="","",IF(AA6>0,1,0)) | AD6: =AD5+IF(AA6="",0,AA6) | AE6: =MAX(AE5,AD6) | AF6: =AE6-AD6
A7: =ROW()-2 | I7: =IFERROR(ABS(H7-G7),"") | L7: =IF(K7="","",IF(K7>=Dashboard!$B$11,"A+","B-")) | O7: =IF(OR(N7="",F7=""),"",IF(OR(AND(F7="Up",N7="Long"),AND(F7="Down",N7="Short")),"OK","CHECK")) | X7: =IFERROR(ABS(Q7-R7)/Dashboard!$B$9*Dashboard!$B$10*W7,"") | Y7: =IFERROR(IF(N7="Long",U7-Q7,IF(N7="Short",Q7-U7,"")),"") | Z7: =IFERROR(Y7/Dashboard!$B$9,"") | AA7: =IFERROR(Z7*Dashboard!$B$10*W7,"") | AB7: =IFERROR(AA7/X7,"") | AC7: =IF(AA7="","",IF(AA7>0,1,0)) | AD7: =AD6+IF(AA7="",0,AA7) | AE7: =MAX(AE6,AD7) | AF7: =AE7-AD7
A8: =ROW()-2 | I8: =IFERROR(ABS(H8-G8),"") | L8: =IF(K8="","",IF(K8>=Dashboard!$B$11,"A+","B-")) | O8: =IF(OR(N8="",F8=""),"",IF(OR(AND(F8="Up",N8="Long"),AND(F8="Down",N8="Short")),"OK","CHECK")) | X8: =IFERROR(ABS(Q8-R8)/Dashboard!$B$9*Dashboard!$B$10*W8,"") | Y8: =IFERROR(IF(N8="Long",U8-Q8,IF(N8="Short",Q8-U8,"")),"") | Z8: =IFERROR(Y8/Dashboard!$B$9,"") | AA8: =IFERROR(Z8*Dashboard!$B$10*W8,"") | AB8: =IFERROR(AA8/X8,"") | AC8: =IF(AA8="","",IF(AA8>0,1,0)) | AD8: =AD7+IF(AA8="",0,AA8) | AE8: =MAX(AE7,AD8) | AF8: =AE8-AD8
A9: =ROW()-2 | I9: =IFERROR(ABS(H9-G9),"") | L9: =IF(K9="","",IF(K9>=Dashboard!$B$11,"A+","B-")) | O9: =IF(OR(N9="",F9=""),"",IF(OR(AND(F9="Up",N9="Long"),AND(F9="Down",N9="Short")),"OK","CHECK")) | X9: =IFERROR(ABS(Q9-R9)/Dashboard!$B$9*Dashboard!$B$10*W9,"") | Y9: =IFERROR(IF(N9="Long",U9-Q9,IF(N9="Short",Q9-U9,"")),"") | Z9: =IFERROR(Y9/Dashboard!$B$9,"") | AA9: =IFERROR(Z9*Dashboard!$B$10*W9,"") | AB9: =IFERROR(AA9/X9,"") | AC9: =IF(AA9="","",IF(AA9>0,1,0)) | AD9: =AD8+IF(AA9="",0,AA9) | AE9: =MAX(AE8,AD9) | AF9: =AE9-AD9
A10: =ROW()-2 | I10: =IFERROR(ABS(H10-G10),"") | L10: =IF(K10="","",IF(K10>=Dashboard!$B$11,"A+","B-")) | O10: =IF(OR(N10="",F10=""),"",IF(OR(AND(F10="Up",N10="Long"),AND(F10="Down",N10="Short")),"OK","CHECK")) | X10: =IFERROR(ABS(Q10-R10)/Dashboard!$B$9*Dashboard!$B$10*W10,"") | Y10: =IFERROR(IF(N10="Long",U10-Q10,IF(N10="Short",Q10-U10,"")),"") | Z10: =IFERROR(Y10/Dashboard!$B$9,"") | AA10: =IFERROR(Z10*Dashboard!$B$10*W10,"") | AB10: =IFERROR(AA10/X10,"") | AC10: =IF(AA10="","",IF(AA10>0,1,0)) | AD10: =AD9+IF(AA10="",0,AA10) | AE10: =MAX(AE9,AD10) | AF10: =AE10-AD10
A11: =ROW()-2 | I11: =IFERROR(ABS(H11-G11),"") | L11: =IF(K11="","",IF(K11>=Dashboard!$B$11,"A+","B-")) | O11: =IF(OR(N11="",F11=""),"",IF(OR(AND(F11="Up",N11="Long"),AND(F11="Down",N11="Short")),"OK","CHECK")) | X11: =IFERROR(ABS(Q11-R11)/Dashboard!$B$9*Dashboard!$B$10*W11,"") | Y11: =IFERROR(IF(N11="Long",U11-Q11,IF(N11="Short",Q11-U11,"")),"") | Z11: =IFERROR(Y11/Dashboard!$B$9,"") | AA11: =IFERROR(Z11*Dashboard!$B$10*W11,"") | AB11: =IFERROR(AA11/X11,"") | AC11: =IF(AA11="","",IF(AA11>0,1,0)) | AD11: =AD10+IF(AA11="",0,AA11) | AE11: =MAX(AE10,AD11) | AF11: =AE11-AD11
A12: =ROW()-2 | I12: =IFERROR(ABS(H12-G12),"") | L12: =IF(K12="","",IF(K12>=Dashboard!$B$11,"A+","B-")) | O12: =IF(OR(N12="",F12=""),"",IF(OR(AND(F12="Up",N12="Long"),AND(F12="Down",N12="Short")),"OK","CHECK")) | X12: =IFERROR(ABS(Q12-R12)/Dashboard!$B$9*Dashboard!$B$10*W12,"") | Y12: =IFERROR(IF(N12="Long",U12-Q12,IF(N12="Short",Q12-U12,"")),"") | Z12: =IFERROR(Y12/Dashboard!$B$9,"") | AA12: =IFERROR(Z12*Dashboard!$B$10*W12,"") | AB12: =IFERROR(AA12/X12,"") | AC12: =IF(AA12="","",IF(AA12>0,1,0)) | AD12: =AD11+IF(AA12="",0,AA12) | AE12: =MAX(AE11,AD12) | AF12: =AE12-AD12
A13: =ROW()-2 | I13: =IFERROR(ABS(H13-G13),"") | L13: =IF(K13="","",IF(K13>=Dashboard!$B$11,"A+","B-")) | O13: =IF(OR(N13="",F13=""),"",IF(OR(AND(F13="Up",N13="Long"),AND(F13="Down",N13="Short")),"OK","CHECK")) | X13: =IFERROR(ABS(Q13-R13)/Dashboard!$B$9*Dashboard!$B$10*W13,"") | Y13: =IFERROR(IF(N13="Long",U13-Q13,IF(N13="Short",Q13-U13,"")),"") | Z13: =IFERROR(Y13/Dashboard!$B$9,"") | AA13: =IFERROR(Z13*Dashboard!$B$10*W13,"") | AB13: =IFERROR(AA13/X13,"") | AC13: =IF(AA13="","",IF(AA13>0,1,0)) | AD13: =AD12+IF(AA13="",0,AA13) | AE13: =MAX(AE12,AD13) | AF13: =AE13-AD13
A14: =ROW()-2 | I14: =IFERROR(ABS(H14-G14),"") | L14: =IF(K14="","",IF(K14>=Dashboard!$B$11,"A+","B-")) | O14: =IF(OR(N14="",F14=""),"",IF(OR(AND(F14="Up",N14="Long"),AND(F14="Down",N14="Short")),"OK","CHECK")) | X14: =IFERROR(ABS(Q14-R14)/Dashboard!$B$9*Dashboard!$B$10*W14,"") | Y14: =IFERROR(IF(N14="Long",U14-Q14,IF(N14="Short",Q14-U14,"")),"") | Z14: =IFERROR(Y14/Dashboard!$B$9,"") | AA14: =IFERROR(Z14*Dashboard!$B$10*W14,"") | AB14: =IFERROR(AA14/X14,"") | AC14: =IF(AA14="","",IF(AA14>0,1,0)) | AD14: =AD13+IF(AA14="",0,AA14) | AE14: =MAX(AE13,AD14) | AF14: =AE14-AD14
A15: =ROW()-2 | I15: =IFERROR(ABS(H15-G15),"") | L15: =IF(K15="","",IF(K15>=Dashboard!$B$11,"A+","B-")) | O15: =IF(OR(N15="",F15=""),"",IF(OR(AND(F15="Up",N15="Long"),AND(F15="Down",N15="Short")),"OK","CHECK")) | X15: =IFERROR(ABS(Q15-R15)/Dashboard!$B$9*Dashboard!$B$10*W15,"") | Y15: =IFERROR(IF(N15="Long",U15-Q15,IF(N15="Short",Q15-U15,"")),"") | Z15: =IFERROR(Y15/Dashboard!$B$9,"") | AA15: =IFERROR(Z15*Dashboard!$B$10*W15,"") | AB15: =IFERROR(AA15/X15,"") | AC15: =IF(AA15="","",IF(AA15>0,1,0)) | AD15: =AD14+IF(AA15="",0,AA15) | AE15: =MAX(AE14,AD15) | AF15: =AE15-AD15
... A152: =ROW()-2 | I152: =IFERROR(ABS(H152-G152),"") | L152: =IF(K152="","",IF(K152>=Dashboard!$B$11,"A+","B-")) | O152: =IF(OR(N152="",F152=""),"",IF(OR(AND(F152="Up",N152="Long"),AND(F152="Down",N152="Short")),"OK","CHECK")) | X152: =IFERROR(ABS(Q152-R152)/Dashboard!$B$9*Dashboard!$B$10*W152,"") | Y152: =IFERROR(IF(N152="Long",U152-Q152,IF(N152="Short",Q152-U152,"")),"") | Z152: =IFERROR(Y152/Dashboard!$B$9,"") | AA152: =IFERROR(Z152*Dashboard!$B$10*W152,"") | AB152: =IFERROR(AA152/X152,"") | AC152: =IF(AA152="","",IF(AA152>0,1,0)) | AD152: =AD151+IF(AA152="",0,AA152) | AE152: =MAX(AE151,AD152) | AF152: =AE152-AD152

Sheet Daily Summary
A1: Date (enter manually) | B1: Trades | C1: Wins | D1: Losses | E1: Daily PnL ($) | F1: Daily PnL (% of Start Bal) | G1: Cumulative Equity, EOD ($) | H1: HWM, capped at Lock Point ($) | I1: MLL Floor ($) | J1: Cushion to Floor ($) | K1: Breach?
B2: =IF($A2="","",COUNTIFS('Trade Log'!$B$3:$B$152,$A2)) | C2: =IF($A2="","",COUNTIFS('Trade Log'!$B$3:$B$152,$A2,'Trade Log'!$AC$3:$AC$152,1)) | D2: =IF($A2="","",COUNTIFS('Trade Log'!$B$3:$B$152,$A2,'Trade Log'!$AC$3:$AC$152,0)) | E2: =IF($A2="","",SUMIFS('Trade Log'!$AA$3:$AA$152,'Trade Log'!$B$3:$B$152,$A2)) | F2: =IFERROR(E2/Dashboard!$B$4,"") | G2: =IF($A2="","",Dashboard!$B$4+SUMIFS('Trade Log'!$AA$3:$AA$152,'Trade Log'!$B$3:$B$152,"<="&$A2)) | H2: =IF($A2="","",MIN(Dashboard!$B$7,MAX(Dashboard!$B$4,G2))) | I2: =IF($A2="","",H2-Dashboard!$B$5) | J2: =IF($A2="","",G2-I2) | K2: =IF($A2="","",IF(G2<I2,"BREACH","ok"))
B3: =IF($A3="","",COUNTIFS('Trade Log'!$B$3:$B$152,$A3)) | C3: =IF($A3="","",COUNTIFS('Trade Log'!$B$3:$B$152,$A3,'Trade Log'!$AC$3:$AC$152,1)) | D3: =IF($A3="","",COUNTIFS('Trade Log'!$B$3:$B$152,$A3,'Trade Log'!$AC$3:$AC$152,0)) | E3: =IF($A3="","",SUMIFS('Trade Log'!$AA$3:$AA$152,'Trade Log'!$B$3:$B$152,$A3)) | F3: =IFERROR(E3/Dashboard!$B$4,"") | G3: =IF($A3="","",Dashboard!$B$4+SUMIFS('Trade Log'!$AA$3:$AA$152,'Trade Log'!$B$3:$B$152,"<="&$A3)) | H3: =IF($A3="","",MIN(Dashboard!$B$7,MAX(IF(H2="",Dashboard!$B$4,H2),G3))) | I3: =IF($A3="","",H3-Dashboard!$B$5) | J3: =IF($A3="","",G3-I3) | K3: =IF($A3="","",IF(G3<I3,"BREACH","ok"))
B4: =IF($A4="","",COUNTIFS('Trade Log'!$B$3:$B$152,$A4)) | C4: =IF($A4="","",COUNTIFS('Trade Log'!$B$3:$B$152,$A4,'Trade Log'!$AC$3:$AC$152,1)) | D4: =IF($A4="","",COUNTIFS('Trade Log'!$B$3:$B$152,$A4,'Trade Log'!$AC$3:$AC$152,0)) | E4: =IF($A4="","",SUMIFS('Trade Log'!$AA$3:$AA$152,'Trade Log'!$B$3:$B$152,$A4)) | F4: =IFERROR(E4/Dashboard!$B$4,"") | G4: =IF($A4="","",Dashboard!$B$4+SUMIFS('Trade Log'!$AA$3:$AA$152,'Trade Log'!$B$3:$B$152,"<="&$A4)) | H4: =IF($A4="","",MIN(Dashboard!$B$7,MAX(IF(H3="",Dashboard!$B$4,H3),G4))) | I4: =IF($A4="","",H4-Dashboard!$B$5) | J4: =IF($A4="","",G4-I4) | K4: =IF($A4="","",IF(G4<I4,"BREACH","ok"))
B5: =IF($A5="","",COUNTIFS('Trade Log'!$B$3:$B$152,$A5)) | C5: =IF($A5="","",COUNTIFS('Trade Log'!$B$3:$B$152,$A5,'Trade Log'!$AC$3:$AC$152,1)) | D5: =IF($A5="","",COUNTIFS('Trade Log'!$B$3:$B$152,$A5,'Trade Log'!$AC$3:$AC$152,0)) | E5: =IF($A5="","",SUMIFS('Trade Log'!$AA$3:$AA$152,'Trade Log'!$B$3:$B$152,$A5)) | F5: =IFERROR(E5/Dashboard!$B$4,"") | G5: =IF($A5="","",Dashboard!$B$4+SUMIFS('Trade Log'!$AA$3:$AA$152,'Trade Log'!$B$3:$B$152,"<="&$A5)) | H5: =IF($A5="","",MIN(Dashboard!$B$7,MAX(IF(H4="",Dashboard!$B$4,H4),G5))) | I5: =IF($A5="","",H5-Dashboard!$B$5) | J5: =IF($A5="","",G5-I5) | K5: =IF($A5="","",IF(G5<I5,"BREACH","ok"))
B6: =IF($A6="","",COUNTIFS('Trade Log'!$B$3:$B$152,$A6)) | C6: =IF($A6="","",COUNTIFS('Trade Log'!$B$3:$B$152,$A6,'Trade Log'!$AC$3:$AC$152,1)) | D6: =IF($A6="","",COUNTIFS('Trade Log'!$B$3:$B$152,$A6,'Trade Log'!$AC$3:$AC$152,0)) | E6: =IF($A6="","",SUMIFS('Trade Log'!$AA$3:$AA$152,'Trade Log'!$B$3:$B$152,$A6)) | F6: =IFERROR(E6/Dashboard!$B$4,"") | G6: =IF($A6="","",Dashboard!$B$4+SUMIFS('Trade Log'!$AA$3:$AA$152,'Trade Log'!$B$3:$B$152,"<="&$A6)) | H6: =IF($A6="","",MIN(Dashboard!$B$7,MAX(IF(H5="",Dashboard!$B$4,H5),G6))) | I6: =IF($A6="","",H6-Dashboard!$B$5) | J6: =IF($A6="","",G6-I6) | K6: =IF($A6="","",IF(G6<I6,"BREACH","ok"))
B7: =IF($A7="","",COUNTIFS('Trade Log'!$B$3:$B$152,$A7)) | C7: =IF($A7="","",COUNTIFS('Trade Log'!$B$3:$B$152,$A7,'Trade Log'!$AC$3:$AC$152,1)) | D7: =IF($A7="","",COUNTIFS('Trade Log'!$B$3:$B$152,$A7,'Trade Log'!$AC$3:$AC$152,0)) | E7: =IF($A7="","",SUMIFS('Trade Log'!$AA$3:$AA$152,'Trade Log'!$B$3:$B$152,$A7)) | F7: =IFERROR(E7/Dashboard!$B$4,"") | G7: =IF($A7="","",Dashboard!$B$4+SUMIFS('Trade Log'!$AA$3:$AA$152,'Trade Log'!$B$3:$B$152,"<="&$A7)) | H7: =IF($A7="","",MIN(Dashboard!$B$7,MAX(IF(H6="",Dashboard!$B$4,H6),G7))) | I7: =IF($A7="","",H7-Dashboard!$B$5) | J7: =IF($A7="","",G7-I7) | K7: =IF($A7="","",IF(G7<I7,"BREACH","ok"))
B8: =IF($A8="","",COUNTIFS('Trade Log'!$B$3:$B$152,$A8)) | C8: =IF($A8="","",COUNTIFS('Trade Log'!$B$3:$B$152,$A8,'Trade Log'!$AC$3:$AC$152,1)) | D8: =IF($A8="","",COUNTIFS('Trade Log'!$B$3:$B$152,$A8,'Trade Log'!$AC$3:$AC$152,0)) | E8: =IF($A8="","",SUMIFS('Trade Log'!$AA$3:$AA$152,'Trade Log'!$B$3:$B$152,$A8)) | F8: =IFERROR(E8/Dashboard!$B$4,"") | G8: =IF($A8="","",Dashboard!$B$4+SUMIFS('Trade Log'!$AA$3:$AA$152,'Trade Log'!$B$3:$B$152,"<="&$A8)) | H8: =IF($A8="","",MIN(Dashboard!$B$7,MAX(IF(H7="",Dashboard!$B$4,H7),G8))) | I8: =IF($A8="","",H8-Dashboard!$B$5) | J8: =IF($A8="","",G8-I8) | K8: =IF($A8="","",IF(G8<I8,"BREACH","ok"))
B9: =IF($A9="","",COUNTIFS('Trade Log'!$B$3:$B$152,$A9)) | C9: =IF($A9="","",COUNTIFS('Trade Log'!$B$3:$B$152,$A9,'Trade Log'!$AC$3:$AC$152,1)) | D9: =IF($A9="","",COUNTIFS('Trade Log'!$B$3:$B$152,$A9,'Trade Log'!$AC$3:$AC$152,0)) | E9: =IF($A9="","",SUMIFS('Trade Log'!$AA$3:$AA$152,'Trade Log'!$B$3:$B$152,$A9)) | F9: =IFERROR(E9/Dashboard!$B$4,"") | G9: =IF($A9="","",Dashboard!$B$4+SUMIFS('Trade Log'!$AA$3:$AA$152,'Trade Log'!$B$3:$B$152,"<="&$A9)) | H9: =IF($A9="","",MIN(Dashboard!$B$7,MAX(IF(H8="",Dashboard!$B$4,H8),G9))) | I9: =IF($A9="","",H9-Dashboard!$B$5) | J9: =IF($A9="","",G9-I9) | K9: =IF($A9="","",IF(G9<I9,"BREACH","ok"))
B10: =IF($A10="","",COUNTIFS('Trade Log'!$B$3:$B$152,$A10)) | C10: =IF($A10="","",COUNTIFS('Trade Log'!$B$3:$B$152,$A10,'Trade Log'!$AC$3:$AC$152,1)) | D10: =IF($A10="","",COUNTIFS('Trade Log'!$B$3:$B$152,$A10,'Trade Log'!$AC$3:$AC$152,0)) | E10: =IF($A10="","",SUMIFS('Trade Log'!$AA$3:$AA$152,'Trade Log'!$B$3:$B$152,$A10)) | F10: =IFERROR(E10/Dashboard!$B$4,"") | G10: =IF($A10="","",Dashboard!$B$4+SUMIFS('Trade Log'!$AA$3:$AA$152,'Trade Log'!$B$3:$B$152,"<="&$A10)) | H10: =IF($A10="","",MIN(Dashboard!$B$7,MAX(IF(H9="",Dashboard!$B$4,H9),G10))) | I10: =IF($A10="","",H10-Dashboard!$B$5) | J10: =IF($A10="","",G10-I10) | K10: =IF($A10="","",IF(G10<I10,"BREACH","ok"))
B11: =IF($A11="","",COUNTIFS('Trade Log'!$B$3:$B$152,$A11)) | C11: =IF($A11="","",COUNTIFS('Trade Log'!$B$3:$B$152,$A11,'Trade Log'!$AC$3:$AC$152,1)) | D11: =IF($A11="","",COUNTIFS('Trade Log'!$B$3:$B$152,$A11,'Trade Log'!$AC$3:$AC$152,0)) | E11: =IF($A11="","",SUMIFS('Trade Log'!$AA$3:$AA$152,'Trade Log'!$B$3:$B$152,$A11)) | F11: =IFERROR(E11/Dashboard!$B$4,"") | G11: =IF($A11="","",Dashboard!$B$4+SUMIFS('Trade Log'!$AA$3:$AA$152,'Trade Log'!$B$3:$B$152,"<="&$A11)) | H11: =IF($A11="","",MIN(Dashboard!$B$7,MAX(IF(H10="",Dashboard!$B$4,H10),G11))) | I11: =IF($A11="","",H11-Dashboard!$B$5) | J11: =IF($A11="","",G11-I11) | K11: =IF($A11="","",IF(G11<I11,"BREACH","ok"))
B12: =IF($A12="","",COUNTIFS('Trade Log'!$B$3:$B$152,$A12)) | C12: =IF($A12="","",COUNTIFS('Trade Log'!$B$3:$B$152,$A12,'Trade Log'!$AC$3:$AC$152,1)) | D12: =IF($A12="","",COUNTIFS('Trade Log'!$B$3:$B$152,$A12,'Trade Log'!$AC$3:$AC$152,0)) | E12: =IF($A12="","",SUMIFS('Trade Log'!$AA$3:$AA$152,'Trade Log'!$B$3:$B$152,$A12)) | F12: =IFERROR(E12/Dashboard!$B$4,"") | G12: =IF($A12="","",Dashboard!$B$4+SUMIFS('Trade Log'!$AA$3:$AA$152,'Trade Log'!$B$3:$B$152,"<="&$A12)) | H12: =IF($A12="","",MIN(Dashboard!$B$7,MAX(IF(H11="",Dashboard!$B$4,H11),G12))) | I12: =IF($A12="","",H12-Dashboard!$B$5) | J12: =IF($A12="","",G12-I12) | K12: =IF($A12="","",IF(G12<I12,"BREACH","ok"))
B13: =IF($A13="","",COUNTIFS('Trade Log'!$B$3:$B$152,$A13)) | C13: =IF($A13="","",COUNTIFS('Trade Log'!$B$3:$B$152,$A13,'Trade Log'!$AC$3:$AC$152,1)) | D13: =IF($A13="","",COUNTIFS('Trade Log'!$B$3:$B$152,$A13,'Trade Log'!$AC$3:$AC$152,0)) | E13: =IF($A13="","",SUMIFS('Trade Log'!$AA$3:$AA$152,'Trade Log'!$B$3:$B$152,$A13)) | F13: =IFERROR(E13/Dashboard!$B$4,"") | G13: =IF($A13="","",Dashboard!$B$4+SUMIFS('Trade Log'!$AA$3:$AA$152,'Trade Log'!$B$3:$B$152,"<="&$A13)) | H13: =IF($A13="","",MIN(Dashboard!$B$7,MAX(IF(H12="",Dashboard!$B$4,H12),G13))) | I13: =IF($A13="","",H13-Dashboard!$B$5) | J13: =IF($A13="","",G13-I13) | K13: =IF($A13="","",IF(G13<I13,"BREACH","ok"))
B14: =IF($A14="","",COUNTIFS('Trade Log'!$B$3:$B$152,$A14)) | C14: =IF($A14="","",COUNTIFS('Trade Log'!$B$3:$B$152,$A14,'Trade Log'!$AC$3:$AC$152,1)) | D14: =IF($A14="","",COUNTIFS('Trade Log'!$B$3:$B$152,$A14,'Trade Log'!$AC$3:$AC$152,0)) | E14: =IF($A14="","",SUMIFS('Trade Log'!$AA$3:$AA$152,'Trade Log'!$B$3:$B$152,$A14)) | F14: =IFERROR(E14/Dashboard!$B$4,"") | G14: =IF($A14="","",Dashboard!$B$4+SUMIFS('Trade Log'!$AA$3:$AA$152,'Trade Log'!$B$3:$B$152,"<="&$A14)) | H14: =IF($A14="","",MIN(Dashboard!$B$7,MAX(IF(H13="",Dashboard!$B$4,H13),G14))) | I14: =IF($A14="","",H14-Dashboard!$B$5) | J14: =IF($A14="","",G14-I14) | K14: =IF($A14="","",IF(G14<I14,"BREACH","ok"))
... B151: =IF($A151="","",COUNTIFS('Trade Log'!$B$3:$B$152,$A151)) | C151: =IF($A151="","",COUNTIFS('Trade Log'!$B$3:$B$152,$A151,'Trade Log'!$AC$3:$AC$152,1)) | D151: =IF($A151="","",COUNTIFS('Trade Log'!$B$3:$B$152,$A151,'Trade Log'!$AC$3:$AC$152,0)) | E151: =IF($A151="","",SUMIFS('Trade Log'!$AA$3:$AA$152,'Trade Log'!$B$3:$B$152,$A151)) | F151: =IFERROR(E151/Dashboard!$B$4,"") | G151: =IF($A151="","",Dashboard!$B$4+SUMIFS('Trade Log'!$AA$3:$AA$152,'Trade Log'!$B$3:$B$152,"<="&$A151)) | H151: =IF($A151="","",MIN(Dashboard!$B$7,MAX(IF(H150="",Dashboard!$B$4,H150),G151))) | I151: =IF($A151="","",H151-Dashboard!$B$5) | J151: =IF($A151="","",G151-I151) | K151: =IF($A151="","",IF(G151<I151,"BREACH","ok"))
